[2024-12-19T21:41:16.720+0000] {local_task_job_runner.py:123} INFO - ::group::Pre task execution logs
[2024-12-19T21:41:16.749+0000] {taskinstance.py:2613} INFO - Dependencies all met for dep_context=non-requeueable deps ti=<TaskInstance: fintech_etl_pipeline.run_dashboard manual__2024-12-19T21:39:28.868330+00:00 [queued]>
[2024-12-19T21:41:16.761+0000] {taskinstance.py:2613} INFO - Dependencies all met for dep_context=requeueable deps ti=<TaskInstance: fintech_etl_pipeline.run_dashboard manual__2024-12-19T21:39:28.868330+00:00 [queued]>
[2024-12-19T21:41:16.762+0000] {taskinstance.py:2866} INFO - Starting attempt 1 of 2
[2024-12-19T21:41:16.785+0000] {taskinstance.py:2889} INFO - Executing <Task(BashOperator): run_dashboard> on 2024-12-19 21:39:28.868330+00:00
[2024-12-19T21:41:16.799+0000] {warnings.py:112} WARNING - /home/***/.local/lib/python3.12/site-packages/***/task/task_runner/standard_task_runner.py:70: DeprecationWarning:

This process (pid=336) is multi-threaded, use of fork() may lead to deadlocks in the child.


[2024-12-19T21:41:16.802+0000] {standard_task_runner.py:72} INFO - Started process 361 to run task
[2024-12-19T21:41:16.802+0000] {standard_task_runner.py:104} INFO - Running: ['***', 'tasks', 'run', 'fintech_etl_pipeline', 'run_dashboard', 'manual__2024-12-19T21:39:28.868330+00:00', '--job-id', '41', '--raw', '--subdir', 'DAGS_FOLDER/fintech_dag.py', '--cfg-path', '/tmp/tmptu_xszb3']
[2024-12-19T21:41:16.804+0000] {standard_task_runner.py:105} INFO - Job 41: Subtask run_dashboard
[2024-12-19T21:41:16.866+0000] {task_command.py:467} INFO - Running <TaskInstance: fintech_etl_pipeline.run_dashboard manual__2024-12-19T21:39:28.868330+00:00 [running]> on host 3f9b1cd285db
[2024-12-19T21:41:16.985+0000] {taskinstance.py:3132} INFO - Exporting env vars: AIRFLOW_CTX_DAG_OWNER='Zeyad_Habash' AIRFLOW_CTX_DAG_ID='fintech_etl_pipeline' AIRFLOW_CTX_TASK_ID='run_dashboard' AIRFLOW_CTX_EXECUTION_DATE='2024-12-19T21:39:28.868330+00:00' AIRFLOW_CTX_TRY_NUMBER='1' AIRFLOW_CTX_DAG_RUN_ID='manual__2024-12-19T21:39:28.868330+00:00'
[2024-12-19T21:41:16.987+0000] {taskinstance.py:731} INFO - ::endgroup::
[2024-12-19T21:41:17.012+0000] {subprocess.py:78} INFO - Tmp dir root location: /tmp
[2024-12-19T21:41:17.013+0000] {subprocess.py:88} INFO - Running command: ['/usr/bin/bash', '-c', 'streamlit run ./dags/fintech_dashboard.py']
[2024-12-19T21:41:17.060+0000] {subprocess.py:99} INFO - Output:
[2024-12-19T21:41:18.347+0000] {subprocess.py:106} INFO - Usage: streamlit run [OPTIONS] TARGET [ARGS]...
[2024-12-19T21:41:18.350+0000] {subprocess.py:106} INFO - Try 'streamlit run --help' for help.
[2024-12-19T21:41:18.352+0000] {subprocess.py:106} INFO - 
[2024-12-19T21:41:18.353+0000] {subprocess.py:106} INFO - Error: Invalid value: File does not exist: ./dags/fintech_dashboard.py
[2024-12-19T21:41:18.475+0000] {subprocess.py:110} INFO - Command exited with return code 2
[2024-12-19T21:41:18.494+0000] {taskinstance.py:3311} ERROR - Task failed with exception
Traceback (most recent call last):
  File "/home/airflow/.local/lib/python3.12/site-packages/airflow/models/taskinstance.py", line 767, in _execute_task
    result = _execute_callable(context=context, **execute_callable_kwargs)
             ^^^^^^^^^^^^^^^^^^^^^^^^^^^^^^^^^^^^^^^^^^^^^^^^^^^^^^^^^^^^^
  File "/home/airflow/.local/lib/python3.12/site-packages/airflow/models/taskinstance.py", line 733, in _execute_callable
    return ExecutionCallableRunner(
           ^^^^^^^^^^^^^^^^^^^^^^^^
  File "/home/airflow/.local/lib/python3.12/site-packages/airflow/utils/operator_helpers.py", line 252, in run
    return self.func(*args, **kwargs)
           ^^^^^^^^^^^^^^^^^^^^^^^^^^
  File "/home/airflow/.local/lib/python3.12/site-packages/airflow/models/baseoperator.py", line 417, in wrapper
    return func(self, *args, **kwargs)
           ^^^^^^^^^^^^^^^^^^^^^^^^^^^
  File "/home/airflow/.local/lib/python3.12/site-packages/airflow/operators/bash.py", line 276, in execute
    raise AirflowException(
airflow.exceptions.AirflowException: Bash command failed. The command returned a non-zero exit code 2.
[2024-12-19T21:41:18.511+0000] {taskinstance.py:1225} INFO - Marking task as UP_FOR_RETRY. dag_id=fintech_etl_pipeline, task_id=run_dashboard, run_id=manual__2024-12-19T21:39:28.868330+00:00, execution_date=20241219T213928, start_date=20241219T214116, end_date=20241219T214118
[2024-12-19T21:41:18.545+0000] {taskinstance.py:340} INFO - ::group::Post task execution logs
[2024-12-19T21:41:18.548+0000] {standard_task_runner.py:124} ERROR - Failed to execute job 41 for task run_dashboard (Bash command failed. The command returned a non-zero exit code 2.; 361)
Traceback (most recent call last):
  File "/home/airflow/.local/lib/python3.12/site-packages/airflow/task/task_runner/standard_task_runner.py", line 117, in _start_by_fork
    ret = args.func(args, dag=self.dag)
          ^^^^^^^^^^^^^^^^^^^^^^^^^^^^^
  File "/home/airflow/.local/lib/python3.12/site-packages/airflow/cli/cli_config.py", line 49, in command
    return func(*args, **kwargs)
           ^^^^^^^^^^^^^^^^^^^^^
  File "/home/airflow/.local/lib/python3.12/site-packages/airflow/utils/cli.py", line 116, in wrapper
    return f(*args, **kwargs)
           ^^^^^^^^^^^^^^^^^^
  File "/home/airflow/.local/lib/python3.12/site-packages/airflow/cli/commands/task_command.py", line 483, in task_run
    task_return_code = _run_task_by_selected_method(args, _dag, ti)
                       ^^^^^^^^^^^^^^^^^^^^^^^^^^^^^^^^^^^^^^^^^^^^
  File "/home/airflow/.local/lib/python3.12/site-packages/airflow/cli/commands/task_command.py", line 256, in _run_task_by_selected_method
    return _run_raw_task(args, ti)
           ^^^^^^^^^^^^^^^^^^^^^^^
  File "/home/airflow/.local/lib/python3.12/site-packages/airflow/cli/commands/task_command.py", line 341, in _run_raw_task
    return ti._run_raw_task(
           ^^^^^^^^^^^^^^^^^
  File "/home/airflow/.local/lib/python3.12/site-packages/airflow/utils/session.py", line 97, in wrapper
    return func(*args, session=session, **kwargs)
           ^^^^^^^^^^^^^^^^^^^^^^^^^^^^^^^^^^^^^^
  File "/home/airflow/.local/lib/python3.12/site-packages/airflow/models/taskinstance.py", line 3005, in _run_raw_task
    return _run_raw_task(
           ^^^^^^^^^^^^^^
  File "/home/airflow/.local/lib/python3.12/site-packages/airflow/models/taskinstance.py", line 273, in _run_raw_task
    TaskInstance._execute_task_with_callbacks(
  File "/home/airflow/.local/lib/python3.12/site-packages/airflow/models/taskinstance.py", line 3159, in _execute_task_with_callbacks
    result = self._execute_task(context, task_orig)
             ^^^^^^^^^^^^^^^^^^^^^^^^^^^^^^^^^^^^^^
  File "/home/airflow/.local/lib/python3.12/site-packages/airflow/models/taskinstance.py", line 3183, in _execute_task
    return _execute_task(self, context, task_orig)
           ^^^^^^^^^^^^^^^^^^^^^^^^^^^^^^^^^^^^^^^
  File "/home/airflow/.local/lib/python3.12/site-packages/airflow/models/taskinstance.py", line 767, in _execute_task
    result = _execute_callable(context=context, **execute_callable_kwargs)
             ^^^^^^^^^^^^^^^^^^^^^^^^^^^^^^^^^^^^^^^^^^^^^^^^^^^^^^^^^^^^^
  File "/home/airflow/.local/lib/python3.12/site-packages/airflow/models/taskinstance.py", line 733, in _execute_callable
    return ExecutionCallableRunner(
           ^^^^^^^^^^^^^^^^^^^^^^^^
  File "/home/airflow/.local/lib/python3.12/site-packages/airflow/utils/operator_helpers.py", line 252, in run
    return self.func(*args, **kwargs)
           ^^^^^^^^^^^^^^^^^^^^^^^^^^
  File "/home/airflow/.local/lib/python3.12/site-packages/airflow/models/baseoperator.py", line 417, in wrapper
    return func(self, *args, **kwargs)
           ^^^^^^^^^^^^^^^^^^^^^^^^^^^
  File "/home/airflow/.local/lib/python3.12/site-packages/airflow/operators/bash.py", line 276, in execute
    raise AirflowException(
airflow.exceptions.AirflowException: Bash command failed. The command returned a non-zero exit code 2.
[2024-12-19T21:41:18.582+0000] {local_task_job_runner.py:266} INFO - Task exited with return code 1
[2024-12-19T21:41:18.606+0000] {taskinstance.py:3895} INFO - 0 downstream tasks scheduled from follow-on schedule check
[2024-12-19T21:41:18.609+0000] {local_task_job_runner.py:245} INFO - ::endgroup::
